Workbook
Name Comapny.Name: Parameters!$G$2
Name D.F.Int.Exp: 'Debt Schedule'!$J$21:$N$21
Name D.F.LTDEBT: 'Debt Schedule'!$J$12:$N$12
Name D.F.STDebt: 'Debt Schedule'!$J$11:$N$11
Name D.F.Total.Debt: 'Debt Schedule'!$J$8:$N$8
Name D.H.Int.Expense: 'Debt Schedule'!$G$21:$I$21
Name D.H.LTDebt: 'Debt Schedule'!$G$12:$I$12
Name D.H.STDebt: 'Debt Schedule'!$G$11:$I$11
Name D.H.Total.Debt: 'Debt Schedule'!$G$8:$I$8
Name Discount: DCF!$G$27:$K$27
Name EV.Mult: DCF!$G$40
Name EV.Perp: DCF!$G$35
Name F.Assets: 'Financial Statements'!$J$58:$N$58
Name f.Capital: 'Financial Statements'!$J$80:$N$80
Name F.Cash: 'Financial Statements'!$J$113:$N$113
Name F.Cash.Financing: 'Financial Statements'!$J$109:$N$109
Name F.Cash.Investment: 'Financial Statements'!$J$102:$N$102
Name F.Cash.Ops: 'Financial Statements'!$J$97:$N$97
Name F.COGS: 'Financial Statements'!$J$13:$N$13
Name F.EBIT: 'Financial Statements'!$J$28:$N$28
Name F.EBITDA: DCF!$G$16:$K$16
Name F.Equity: 'Financial Statements'!$J$79:$N$79
Name F.LT.Assets: 'Financial Statements'!$J$57:$N$57
Name F.Margin: 'Financial Statements'!$J$15:$N$15
Name F.Net.Income: 'Financial Statements'!$J$36:$N$36
Name F.OpEx: 'Financial Statements'!$J$26:$N$26
Name F.Pref: 'Financial Statements'!$J$75:$N$75
Name f.revenues: 'Financial Statements'!$J$7:$N$7
Name F.ST.Assets: 'Financial Statements'!$J$48:$N$48
Name forecast.years: Parameters!$J$4
Name GFHIVM.Valuation: DCF!$H$64
Name H.Assets: 'Financial Statements'!$G$58:$I$58
Name H.Capital: 'Financial Statements'!$G$80:$I$80
Name H.Cash: 'Financial Statements'!$G$113:$I$113
Name H.Cash.Financing: 'Financial Statements'!$H$109:$I$109
Name H.Cash.Investment: 'Financial Statements'!$H$102:$I$102
Name H.Cash.Ops: 'Financial Statements'!$H$97:$I$97
Name H.COGS: 'Financial Statements'!$G$13:$I$13
Name H.EBIT: 'Financial Statements'!$G$28:$I$28
Name H.Equity: 'Financial Statements'!$G$79:$I$79
Name H.LT.Assets: 'Financial Statements'!$G$57:$I$57
Name H.Margin: 'Financial Statements'!$G$15:$I$15
Name H.Net.Income: 'Financial Statements'!$G$36:$I$36
Name H.Pref: 'Financial Statements'!$G$75:$I$75
Name H.Revenues: 'Financial Statements'!$G$7:$I$7
Name H.ST.Assets: 'Financial Statements'!$G$48:$I$48
Name market.cap: DCF!$G$6
Name NPV.FCF: DCF!$G$28
Name P.F.Accounts.Payable: Parameters!$J$38:$N$38
Name P.F.Accruds: Parameters!$J$39:$N$39
Name P.F.Accts.Rec.Days: Parameters!$J$35:$N$35
Name P.F.Amorization: Parameters!$J$26:$N$26
Name P.F.Buybacks: Parameters!$J$29:$N$29
Name P.F.CapEx: Parameters!$J$44:$N$44
Name P.F.COGS: Parameters!$J$14:$N$16
Name P.F.Depreciation: Parameters!$J$25:$N$25
Name P.F.Dividends: Parameters!$J$28:$N$28
Name P.F.Int.Exp: 'Debt Schedule'!$J$21:$N$21
Name P.F.Inventory: Parameters!$J$36:$N$36
Name P.F.Inventory.Days: Parameters!$J$36:$N$36

Sheet Parameters
A1: Parameters
B2: Company name | G2: LeBronLiBerty Inc.
B3: Starting Year | G3: 2025
B4: Financial Statements Assumptions | G4: {=_xlfn.SEQUENCE(1,3,start.year)} -> 2025 | H4: 2026 | I4: 2027 | J4: {=_xlfn.SEQUENCE(1,5,I4+1)} -> 2028 | K4: 2029 | L4: 2030 | M4: 2031 | N4: 2032
C5: Revenues
D6: Basketballs | G6: 7900 | H6: 8089 | I6: 8232 | J6: =I6*(1+J10) -> 8403.2354 | K6: =J6*(1+K10) -> 8564.9116 | L6: =K6*(1+L10) -> 8736.3852 | M6: =L6*(1+M10) -> 8907.8815 | N6: =M6*(1+N10) -> 9084.4829
D7: Shoes | G7: 8179 | H7: 8105 | I7: 8375 | J7: =I7*(1+J11) -> 8476.6106 | K7: =J7*(1+K11) -> 8669.2219 | L7: =K7*(1+L11) -> 8820.3061 | M7: =L7*(1+M11) -> 8997.3752 | N7: =M7*(1+N11) -> 9166.0886
D8: Apparel | G8: 8173 | H8: 8174 | I8: 8371 | J8: =I8*(1+J12) -> 8472.386 | K8: =J8*(1+K12) -> 8625.7887 | L8: =K8*(1+L12) -> 8756.1148 | M8: =L8*(1+M12) -> 8901.5323 | N8: =M8*(1+N12) -> 9042.6947
C9: Deltas
D10: {=+D6:D8} -> Basketballs | H10: =+H6/G6-1 -> 0.023924051 | I10: =+I6/H6-1 -> 0.017678329 | J10: =AVERAGE(H10:I10) -> 0.02080119 | K10: =AVERAGE(I10:J10) -> 0.019239759 | L10: =AVERAGE(J10:K10) -> 0.020020474 | M10: =AVERAGE(K10:L10) -> 0.019630117 | N10: =AVERAGE(L10:M10) -> 0.019825296
D11: Shoes | H11: =+H7/G7-1 -> -0.0090475608 | I11: =+I7/H7-1 -> 0.03331277 | J11: =AVERAGE(H11:I11) -> 0.012132605 | K11: =AVERAGE(I11:J11) -> 0.022722687 | L11: =AVERAGE(J11:K11) -> 0.017427646 | M11: =AVERAGE(K11:L11) -> 0.020075167 | N11: =AVERAGE(L11:M11) -> 0.018751406
D12: Apparel | H12: =+H8/G8-1 -> 0.00012235409 | I12: =+I8/H8-1 -> 0.024100807 | J12: =AVERAGE(H12:I12) -> 0.012111581 | K12: =AVERAGE(I12:J12) -> 0.018106194 | L12: =AVERAGE(J12:K12) -> 0.015108887 | M12: =AVERAGE(K12:L12) -> 0.016607541 | N12: =AVERAGE(L12:M12) -> 0.015858214
C13: Costs of Goods Sold
D14: {=+D6:D8} -> Basketballs | G14: 0.48 | H14: 0.47 | I14: 0.49 | J14: =AVERAGE(G14:I14) -> 0.48 | K14: =AVERAGE(H14:J14) -> 0.48 | L14: =AVERAGE(I14:K14) -> 0.48333333 | M14: =AVERAGE(J14:L14) -> 0.48111111 | N14: =AVERAGE(K14:M14) -> 0.48148148
D15: Shoes | G15: 0.47 | H15: 0.45 | I15: 0.48 | J15: =AVERAGE(G15:I15) -> 0.46666667 | K15: =AVERAGE(H15:J15) -> 0.46555556 | L15: =AVERAGE(I15:K15) -> 0.47074074 | M15: =AVERAGE(J15:L15) -> 0.46765432 | N15: =AVERAGE(K15:M15) -> 0.46798354
D16: Apparel | G16: 0.5 | H16: 0.5 | I16: 0.49 | J16: =AVERAGE(G16:I16) -> 0.49666667 | K16: =AVERAGE(H16:J16) -> 0.49555556 | L16: =AVERAGE(I16:K16) -> 0.49407407 | M16: =AVERAGE(J16:L16) -> 0.4954321 | N16: =AVERAGE(K16:M16) -> 0.49502058
C19: OpEx
D20: Rent | G20: 0.03 | H20: =+G20 -> 0.03 | I20: =+H20 -> 0.03 | J20: =+I20 -> 0.03 | K20: =+J20 -> 0.03 | L20: =+K20 -> 0.03 | M20: =+L20 -> 0.03 | N20: =+M20 -> 0.03
D21: Elctricity | G21: 0.025 | H21: =+G21 -> 0.025 | I21: =+H21 -> 0.025 | J21: =+I21 -> 0.025 | K21: =+J21 -> 0.025 | L21: =+K21 -> 0.025 | M21: =+L21 -> 0.025 | N21: =+M21 -> 0.025
D22: Phone | G22: 0.028 | H22: =+G22 -> 0.028 | I22: =+H22 -> 0.028 | J22: =+I22 -> 0.028 | K22: =+J22 -> 0.028 | L22: =+K22 -> 0.028 | M22: =+L22 -> 0.028 | N22: =+M22 -> 0.028
D23: Insurance | G23: 0.031 | H23: =+G23 -> 0.031 | I23: =+H23 -> 0.031 | J23: =+I23 -> 0.031 | K23: =+J23 -> 0.031 | L23: =+K23 -> 0.031 | M23: =+L23 -> 0.031 | N23: =+M23 -> 0.031
D24: Payroll | G24: 0.105 | H24: =+G24 -> 0.105 | I24: =+H24 -> 0.105 | J24: =+I24 -> 0.105 | K24: =+J24 -> 0.105 | L24: =+K24 -> 0.105 | M24: =+L24 -> 0.105 | N24: =+M24 -> 0.105
D25: Depreciation | G25: 2500 | H25: =+G25 -> 2500 | I25: =+H25 -> 2500 | J25: =+I25 -> 2500 | K25: =+J25 -> 2500 | L25: =+K25 -> 2500 | M25: =+L25 -> 2500 | N25: =+M25 -> 2500
D26: Amorizarion | G26: 250 | H26: =+G26 -> 250 | I26: =+H26 -> 250 | J26: =+I26 -> 250 | K26: =+J26 -> 250 | L26: =+K26 -> 250 | M26: =+L26 -> 250 | N26: =+M26 -> 250
C27: Tax Rate | G27: 0.21 | H27: =+G27 -> 0.21 | I27: =+H27 -> 0.21 | J27: =+I27 -> 0.21 | K27: =+J27 -> 0.21 | L27: =+K27 -> 0.21 | M27: =+L27 -> 0.21 | N27: =+M27 -> 0.21
C28: Cash Dividends | G28: 350 | H28: 350 | I28: 375 | J28: 2850 | K28: =+J28 -> 2850 | L28: =+K28 -> 2850 | M28: =+L28 -> 2850 | N28: =+M28 -> 2850
C29: Stock Buybacks | G29: 250 | H29: 250 | I29: 250 | J29: 1500 | K29: =+J29 -> 1500 | L29: =+K29 -> 1500 | M29: =+L29 -> 1500 | N29: =+M29 -> 1500
C32: Balance Sheet Assumptions
D33: Starting Cash | G33: 3500
D34: Working Capital Assumptions
E35: Accounts Receivable (Days of Revenues) | G35: 30 | H35: 35 | I35: 31 | J35: =AVERAGE(H35:I35) -> 33 | K35: =AVERAGE(I35:J35) -> 32 | L35: =AVERAGE(J35:K35) -> 32.5 | M35: =AVERAGE(K35:L35) -> 32.25 | N35: =AVERAGE(L35:M35) -> 32.375
E36: Inventory (days of COGS) | G36: 31 | H36: 32 | I36: 31 | J36: =AVERAGE(H36:I36) -> 31.5 | K36: =AVERAGE(I36:J36) -> 31.25 | L36: =AVERAGE(J36:K36) -> 31.375 | M36: =AVERAGE(K36:L36) -> 31.3125 | N36: =AVERAGE(L36:M36) -> 31.34375
E37: Prepaid Expenses (% Revenues) | G37: 0.02 | H37: =+G37 -> 0.02 | I37: =+H37 -> 0.02 | J37: =AVERAGE(H37:I37) -> 0.02 | K37: =AVERAGE(I37:J37) -> 0.02 | L37: =AVERAGE(J37:K37) -> 0.02 | M37: =AVERAGE(K37:L37) -> 0.02 | N37: =AVERAGE(L37:M37) -> 0.02
E38: Accounts Payable (Dats of COGS) | G38: 30 | H38: 30 | I38: 30 | J38: =AVERAGE(H38:I38) -> 30 | K38: =AVERAGE(I38:J38) -> 30 | L38: =AVERAGE(J38:K38) -> 30 | M38: =AVERAGE(K38:L38) -> 30 | N38: =AVERAGE(L38:M38) -> 30
E39: Accrued Liabilities | G39: 0.02 | H39: =+G39 -> 0.02 | I39: =+H39 -> 0.02 | J39: =AVERAGE(H39:I39) -> 0.02 | K39: =AVERAGE(I39:J39) -> 0.02 | L39: =AVERAGE(J39:K39) -> 0.02 | M39: =AVERAGE(K39:L39) -> 0.02 | N39: =AVERAGE(L39:M39) -> 0.02
D41: PP&E
E42: Starting Gross | G42: 5000
E43: Starting AccDep | G43: 1000
E44: Capital Expenditures (CapEx) | H44: 3000 | I44: =+H44 -> 3000 | J44: =+I44 -> 3000 | K44: =+J44 -> 3000 | L44: =+K44 -> 3000 | M44: =+L44 -> 3000 | N44: =+M44 -> 3000
D45: Starting Goodwill | G45: 2000
...

Sheet Financial Statements
A1: ="Financial Statements of "&Comapny.Name -> Financial Statements of LeBronLiBerty Inc.
B2: Income Statement
C3: Revenues | G3: {=_xlfn.ANCHORARRAY(years)} -> 2025 | H3: 2026 | I3: 2027 | J3: {=_xlfn.SEQUENCE(1,5,I3+1)} -> 2028 | K3: 2029 | L3: 2030 | M3: 2031 | N3: 2032
D4: Basketballs | G4: {=P.H.Revenues} -> 7900 | H4: 8089 | I4: 8232 | J4: {=P.F.Revenues} -> 8403.2354 | K4: 8564.9116 | L4: 8736.3852 | M4: 8907.8815 | N4: 9084.4829
D5: Shoes | G5: 8179 | H5: 8105 | I5: 8375 | J5: 8476.6106 | K5: 8669.2219 | L5: 8820.3061 | M5: 8997.3752 | N5: 9166.0886
D6: Apparel | G6: 8173 | H6: 8174 | I6: 8371 | J6: 8472.386 | K6: 8625.7887 | L6: 8756.1148 | M6: 8901.5323 | N6: 9042.6947
C7: Total Revenues | G7: =SUM(G4:G6) -> 24252 | H7: =SUM(H4:H6) -> 24368 | I7: =SUM(I4:I6) -> 24978 | J7: =SUM(J4:J6) -> 25352.232 | K7: =SUM(K4:K6) -> 25859.922 | L7: =SUM(L4:L6) -> 26312.806 | M7: =SUM(M4:M6) -> 26806.789 | N7: =SUM(N4:N6) -> 27293.266
C9: Cost of Goods Sold
D10: {=+D4:D6} -> Basketballs | G10: {=+P.H.Revenues*(P.H.COGS)} -> 3792 | H10: 3801.83 | I10: 4033.68 | J10: {=P.F.Revenues*P.F.COGS} -> 4033.553 | K10: 4111.1576 | L10: 4222.5862 | M10: 4285.6808 | N10: 4374.0103
D11: Shoes | G11: 3844.13 | H11: 3647.25 | I11: 4020 | J11: 3955.7516 | K11: 4036.0044 | L11: 4152.0774 | M11: 4207.6614 | N11: 4289.5786
D12: Apparel | G12: 4086.5 | H12: 4087 | I12: 4101.79 | J12: 4207.9517 | K12: 4274.5575 | L12: 4326.1693 | M12: 4410.1048 | N12: 4476.3199
C13: Total Revenues | G13: =SUM(G10:G12) -> 11722.63 | H13: =SUM(H10:H12) -> 11536.08 | I13: =SUM(I10:I12) -> 12155.47 | J13: =SUM(J10:J12) -> 12197.256 | K13: =SUM(K10:K12) -> 12421.72 | L13: =SUM(L10:L12) -> 12700.833 | M13: =SUM(M10:M12) -> 12903.447 | N13: =SUM(N10:N12) -> 13139.909
C15: Gross Margin | G15: {=+H.Revenues-H.COGS} -> 12529.37 | H15: 12831.92 | I15: 12822.53 | J15: {=f.revenues-F.COGS} -> 13154.976 | K15: 13438.203 | L15: 13611.973 | M15: 13903.342 | N15: 14153.357
D16: % of Sales | G16: {=+H.Margin/H.Revenues} -> 0.51663244 | H16: 0.52658897 | I16: 0.51335295 | J16: {=+F.Margin/f.revenues} -> 0.51888827 | K16: 0.51965364 | L16: 0.51731363 | M16: 0.51865003 | N16: 0.51856591
C18: OpEx
D19: Rent | G19: {=+P.H.OpEx*H.Revenues} -> 727.56 | H19: 731.04 | I19: 749.34 | J19: {=P.F.OpEx*f.revenues} -> 760.56696 | K19: 775.79767 | L19: 789.38418 | M19: 804.20367 | N19: 818.79799
D20: Elctricity | G20: 606.3 | H20: 609.2 | I20: 624.45 | J20: 633.8058 | K20: 646.49806 | L20: 657.82015 | M20: 670.16972 | N20: 682.33165
D21: Phone | G21: 679.056 | H21: 682.304 | I21: 699.384 | J21: 709.8625 | K21: 724.07782 | L21: 736.75857 | M21: 750.59009 | N21: 764.21145
D22: Insurance | G22: 751.812 | H22: 755.408 | I22: 774.318 | J22: 785.91919 | K22: 801.65759 | L22: 815.69699 | M22: 831.01046 | N22: 846.09125
D23: Payroll | G23: 2546.46 | H23: 2558.64 | I23: 2622.69 | J23: 2661.9844 | K23: 2715.2918 | L23: 2762.8446 | M23: 2814.7128 | N23: 2865.7929
D24: Depreciation | G24: {=+P.H.Depreciation} -> 2500 | H24: 2500 | I24: 2500 | J24: {=P.F.Depreciation} -> 2500 | K24: 2500 | L24: 2500 | M24: 2500 | N24: 2500
D25: Amorizarion | G25: {=+P.H.Amorization} -> 250 | H25: 250 | I25: 250 | J25: {=P.F.Amorization} -> 250 | K25: 250 | L25: 250 | M25: 250 | N25: 250
C26: Net Operating Expenses | G26: =SUM(G19:G25) -> 8061.188 | H26: =SUM(H19:H25) -> 8086.592 | I26: =SUM(I19:I25) -> 8220.182 | J26: =SUM(J19:J25) -> 8302.1388 | K26: =SUM(K19:K25) -> 8413.323 | L26: =SUM(L19:L25) -> 8512.5045 | M26: =SUM(M19:M25) -> 8620.6868 | N26: =SUM(N19:N25) -> 8727.2253
C28: Earnings Before Interest & Taxes (EBIT) | G28: {=+H.Margin-G26:I26} -> 4468.182 | H28: 4745.328 | I28: 4602.348 | J28: {=F.Margin-F.OpEx} -> 4852.8369 | K28: 5024.8798 | L28: 5099.4686 | M28: 5282.6552 | N28: 5426.1321
C30: Interest Expense | G30: {=D.H.Int.Expense} -> 355.625 | H30: 367 | I30: 348.375 | J30: {=D.F.Int.Exp} -> 331.125 | K30: 316.75 | L30: 302.375 | M30: 288 | N30: 273.625
C32: Earnings Befor Taxes(EBT) | G32: {=+_xlfn.ANCHORARRAY(G28)-G30:I30} -> 4112.557 | H32: 4378.328 | I32: 4253.973 | J32: {=+_xlfn.ANCHORARRAY(J28)-_xlfn.ANCHORARRAY(J30)} -> 4521.7119 | K32: 4708.1298 | L32: 4797.0936 | M32: 4994.6552 | N32: 5152.5071
C34: Income Tax Expense | G34: {=+_xlfn.ANCHORARRAY(G32)*Tax.Rate} -> 863.63697 | H34: 919.44888 | I34: 893.33433 | J34: {=_xlfn.ANCHORARRAY(J32)*P.F.Tax} -> 949.55949 | K34: 988.70725 | L34: 1007.3897 | M34: 1048.8776 | N34: 1082.0265
C36: Net Income | G36: {=+_xlfn.ANCHORARRAY(G32)-_xlfn.ANCHORARRAY(G34)} -> 3248.92 | H36: 3458.8791 | I36: 3360.6387 | J36: {=_xlfn.ANCHORARRAY(J32)-_xlfn.ANCHORARRAY(J34)} -> 3572.1524 | K36: 3719.4225 | L36: 3789.704 | M36: 3945.7776 | N36: 4070.4806
C37: Less: Cash Dividends | G37: {=-P.H.Dividends} -> -350 | H37: -350 | I37: -375 | J37: {=-P.F.Dividends} -> -2850 | K37: -2850 | L37: -2850 | M37: -2850 | N37: -2850
C38: Change in Retained Earnings | G38: {=+H.Net.Income+_xlfn.ANCHORARRAY(G37)} -> 2898.92 | H38: 3108.8791 | I38: 2985.6387 | J38: {=_xlfn.ANCHORARRAY(J36)+_xlfn.ANCHORARRAY(J37)} -> 722.15238 | K38: 869.42251 | L38: 939.70397 | M38: 1095.7776 | N38: 1220.4806
B41: Balance Sheet | G41: {=_xlfn.ANCHORARRAY(years)} -> 2025 | H41: 2026 | I41: 2027 | J41: {=_xlfn.SEQUENCE(1,5,I41+1)} -> 2028 | K41: 2029 | L41: 2030 | M41: 2031 | N41: 2032
C42: Assets
D43: Short Term Assets
E44: Cash | G44: {=+H.Cash} -> 3500 | H44: 5484.4421 | I44: 7515.2278 | J44: {=+F.Cash} -> 5999.8567 | K44: 4901.8131 | L44: 3760.4618 | M44: 2832.0617 | N44: 1998.2367
E45: Accounts Receivable | G45: {=+H.Revenues*(P.H.Accts.Rec.Days/365)} -> 1993.3151 | H45: 2336.6575 | I45: 2121.4192 | J45: {=+f.revenues*(P.F.Accts.Rec.Days/365)} -> 2292.1196 | K45: 2267.1713 | L45: 2342.9211 | M45: 2368.5451 | N45: 2420.8753
E46: Inventory | G46: {=+H.COGS*(P.H.Inventory.Days/365)} -> 995.62063 | H46: 1011.3824 | I46: 1032.3824 | J46: {=+F.COGS*(P.F.Inventory.Days/365)} -> 1052.6399 | K46: 1063.5034 | L46: 1091.7497 | M46: 1106.9567 | N46: 1128.3672
E47: Prepaid Expenses | G47: {=+H.Revenues*P.H.Prepaids} -> 485.04 | H47: 487.36 | I47: 499.56 | J47: {=+f.revenues*P.F.Prepaids} -> 507.04464 | K47: 517.19845 | L47: 526.25612 | M47: 536.13578 | N47: 545.86532
D48: Total Shot Term Assets | G48: =SUM(G44:G47) -> 6973.9757 | H48: =SUM(H44:H47) -> 9319.8419 | I48: =SUM(I44:I47) -> 11168.589 | J48: =SUM(J44:J47) -> 9851.6609 | K48: =SUM(K44:K47) -> 8749.6862 | L48: =SUM(L44:L47) -> 7721.3887 | M48: =SUM(M44:M47) -> 6843.6992 | N48: =SUM(N44:N47) -> 6093.3446
D50: Long Term Assets
E51: Property, Plant, Equipment
...

Sheet DCF
A1: ="Discount Cash Flow Analysis for "&Comapny.Name -> Discount Cash Flow Analysis for LeBronLiBerty Inc.
B2: Weighted Average Cost of Capital (WACC)
C3: Assumptions | G3: #VALUE!
D4: Share Price | G4: {=+_FV(G3,"Price")} -> 12.43
D5: Shares Oustanding(mm of shares) | G5: {=_FV(G3,"Shares outstanding",TRUE)/1000000} -> 3987.596
D6: Market Cap ($mm) | G6: {=+_FV(G3,"Market cap",TRUE)/1000000} -> 49565.818
C8: Capital Costs | G8: Ammount | H8: Weight | I8: Cost
D9: Debt | G9: {=_xlfn.TAKE(D.H.Total.Debt,1,-1)} -> 5550 | H9: {=+G9:G11/G12} -> 0.33293442 | I9: {=_xlfn.LET( _xlpm.raw_interest,_xlfn.TAKE(D.H.Int.Expense,1,-1)/G9, _xlpm.tax_shield,100%-Tax.Rate, _xlpm.raw_interest*_xlpm.tax_shield )} -> 0.049588514 | J9: 0.049588514 | K9: 0.049588514
D10: Prefered Stock | G10: {=_xlfn.TAKE(H.Pref,1,-1)} -> 1500 | H10: 0.089982275 | I10: 0.0739
D11: Common Stock | G11: {=_xlfn.TAKE(H.Equity,1,-1)-G10} -> 9619.9497 | H11: 0.57708331 | I11: 0.1171
E12: Total Capital | G12: =SUM(G9:G11) -> 16669.95
C13: Weighted Average Cost of Capital | G13: =SUMPRODUCT(_xlfn.ANCHORARRAY(H9),I9:I11) -> 0.090735868
B15: Free Cash Flow Build up | G15: {=_xlfn.ANCHORARRAY(forecast.years)} -> 2028 | H15: 2029 | I15: 2030 | J15: 2031 | K15: 2032
C16: EBITDA | G16: {=+_xlfn.ANCHORARRAY(G18)-_xlfn.ANCHORARRAY(G17)} -> 7602.8369 | H16: 7774.8798 | I16: 7849.4686 | J16: 8032.6552 | K16: 8176.1321
D17: Less: Depreciation & Amortization | G17: {=-P.F.Depreciation-P.F.Amorization} -> -2750 | H17: -2750 | I17: -2750 | J17: -2750 | K17: -2750
C18: EBIT | G18: {=F.EBIT} -> 4852.8369 | H18: 5024.8798 | I18: 5099.4686 | J18: 5282.6552 | K18: 5426.1321
D19: Less:Income Taxes | G19: {=-_xlfn.ANCHORARRAY(G18)*tax.Rate.} -> -1019.0957 | H19: -1055.2247 | I19: -1070.8884 | J19: -1109.3576 | K19: -1139.4877
C20: EBIAT(NOPAT- Net) | G20: =SUM(G18:G19) -> 3833.7411 | H20: =SUM(H18:H19) -> 3969.655 | I20: =SUM(I18:I19) -> 4028.5802 | J20: =SUM(J18:J19) -> 4173.2976 | K20: =SUM(K18:K19) -> 4286.6444
D21: Adjustments
E22: Add Back: Dep & Amort | G22: {=-_xlfn.ANCHORARRAY(G17)} -> 2750 | H22: 2750 | I22: 2750 | J22: 2750 | K22: 2750
E23: Change in Working Capital | G23: =SUM('Financial Statements'!J92:J96) -> -187.52348 | H23: =SUM('Financial Statements'!K92:K96) -> 32.533914 | I23: =SUM('Financial Statements'!L92:L96) -> -81.055288 | J23: =SUM('Financial Statements'!M92:M96) -> -24.177743 | K23: =SUM('Financial Statements'!N92:N96) -> -54.305554
D24: Unlevered Cash From Operations | G24: {=+G20:K20+_xlfn.ANCHORARRAY(G22)+G23:K23} -> 6396.2176 | H24: 6752.1889 | I24: 6697.5249 | J24: 6899.1199 | K24: 6982.3388
E25: Less:CapEx | G25: {=-P.F.CapEx} -> -3000 | H25: -3000 | I25: -3000 | J25: -3000 | K25: -3000
D26: Unlevered Free Cash Flow | G26: {=_xlfn.ANCHORARRAY(G24)+_xlfn.ANCHORARRAY(G25)} -> 3396.2176 | H26: 3752.1889 | I26: 3697.5249 | J26: 3899.1199 | K26: 3982.3388
E27: Discount factor | G27: =1/(1+WACC)^G101 -> 0.91681224 | H27: =1/(1+WACC)^H101 -> 0.84054469 | I27: =1/(1+WACC)^I101 -> 0.77062167 | J27: =1/(1+WACC)^J101 -> 0.70651538 | K27: =1/(1+WACC)^K101 -> 0.64774195
D28: NPV or FCF | G28: =SUMPRODUCT(unlev.FCF,Discount) -> 14451.285
A30: Terminal Value Estimations
B31: Perpituity Approach
C32: Unlevered FCF in Year 5 | G32: {=_xlfn.TAKE(unlev.FCF,1,-1)} -> 3982.3388
D33: Long Term Growth Rate | G33: 0.03
C34: Estimated FCF Time T+1 | G34: =+G32*(1+G33) -> 4101.809
C35: Estimated Terminal Enterprise Value | G35: =+G34/(WACC-G33) -> 67535.199
B37: Exit EBITDA Multiple Approach
C38: Terminal EBITDA | G38: =Term.Ebitda -> 8176.1321
C39: Expected Market Multiple | G39: 9
D40: EBITDA Terminal Enterprise Value | G40: =+G38*G39 -> 73585.189
B42: Capital Stack
C43: Cash | G43: {=_xlfn.TAKE(F.Cash,1,-1)} -> 1998.2367
C44: Debt | G44: {=_xlfn.TAKE(-D.F.Total.Debt,1,-1)} -> -4250
C45: Prefered Shares | G45: {=_xlfn.TAKE(-F.Pref,1,-1)} -> -1500
...

Sheet Football Field
A1: DCF Football Field and Scenarios for Lebron Liberty v1
B3: Equity Value Per Share
C4: Long Term Growth
B5: =price.perp -> 13.653566 | C5: {=_xlfn.SEQUENCE(1,5,2%,0.25%)} -> 0.02 | D5: 0.0225 | E5: 0.025 | F5: 0.0275 | G5: 0.03
A6: WACC | B6: {=_xlfn.SEQUENCE(5,1,7.5%,1.5%)} -> 0.075
B7: 0.09
B8: 0.105
B9: 0.12
B10: 0.135

Sheet Debt Schedule
A1: Debt Schedule
C2: Debt Table | G2: 2025 | H2: 2026 | I2: 2027 | J2: {=_xlfn.SEQUENCE(1,5,I2+1)} -> 2028 | K2: 2029 | L2: 2030 | M2: 2031 | N2: 2032
C3: Hunington Revolver | G3: 750 | H3: 750 | I3: 750 | J3: 750 | K3: =+J3 -> 750 | L3: =+K3 -> 750 | M3: =+L3 -> 750 | N3: =+M3 -> 750 | O3: =+N3 -> 750
C4: PNC Term Loan | G4: 3250 | H4: 3000 | I4: 2800 | J4: 2500 | K4: =+J4-250 -> 2250 | L4: =+K4-250 -> 2000 | M4: =+L4-250 -> 1750 | N4: =+M4-250 -> 1500 | O4: =+N4-250 -> 1250
C5: Key Bank Term Loan | G5: 2500 | H5: 2500 | I5: 2000 | J5: 2000 | K5: =+J5 -> 2000 | L5: =+K5 -> 2000 | M5: =+L5 -> 2000 | N5: =+M5 -> 2000 | O5: =+N5 -> 2000
C6: tbd | G6: 0 | H6: =+G6 -> 0 | I6: =+H6 -> 0 | J6: =+I6 -> 0 | K6: 0 | L6: 0 | M6: 0 | N6: 0 | O6: 0
C7: tbd | G7: 0 | H7: =+G7 -> 0 | I7: =+H7 -> 0 | J7: =+I7 -> 0 | K7: 0 | L7: 0 | M7: 0 | N7: 0 | O7: 0
B8: Total Debt | G8: =SUM(G3:G7) -> 6500 | H8: =SUM(H3:H7) -> 6250 | I8: =SUM(I3:I7) -> 5550 | J8: =SUM(J3:J7) -> 5250 | K8: =SUM(K3:K7) -> 5000 | L8: =SUM(L3:L7) -> 4750 | M8: =SUM(M3:M7) -> 4500 | N8: =SUM(N3:N7) -> 4250 | O8: =SUM(O3:O7) -> 4000
B10: Current Portion Calculation
C11: Short Term | G11: =+G8-H8 -> 250 | H11: =+H8-I8 -> 700 | I11: =+I8-J8 -> 300 | J11: =+J8-K8 -> 250 | K11: =+K8-L8 -> 250 | L11: =+L8-M8 -> 250 | M11: =+M8-N8 -> 250 | N11: =+N8-O8 -> 250
C12: Long Term | G12: =+G8-G11 -> 6250 | H12: =+H8-H11 -> 5550 | I12: =+I8-I11 -> 5250 | J12: =+J8-J11 -> 5000 | K12: =+K8-K11 -> 4750 | L12: =+L8-L11 -> 4500 | M12: =+M8-M11 -> 4250 | N12: =+N8-N11 -> 4000
B14: Interest Rates
C15: {=+C3:C7} -> Hunington Revolver | G15: 0.075 | H15: 0.076 | I15: 0.0765 | J15: =+I15 -> 0.0765 | K15: =+J15 -> 0.0765 | L15: =+K15 -> 0.0765 | M15: =+L15 -> 0.0765 | N15: =+M15 -> 0.0765
C16: PNC Term Loan | G16: 0.0575 | H16: 0.0575 | I16: 0.0575 | J16: =+I16 -> 0.0575 | K16: =+J16 -> 0.0575 | L16: =+K16 -> 0.0575 | M16: =+L16 -> 0.0575 | N16: =+M16 -> 0.0575
C17: Key Bank Term Loan | G17: 0.045 | H17: 0.055 | I17: 0.065 | J17: =+I17 -> 0.065 | K17: =+J17 -> 0.065 | L17: =+K17 -> 0.065 | M17: =+L17 -> 0.065 | N17: =+M17 -> 0.065
C18: tbd | G18: 9.99 | H18: 9.99 | I18: 9.99 | J18: =+I18 -> 9.99 | K18: =+J18 -> 9.99 | L18: =+K18 -> 9.99 | M18: =+L18 -> 9.99 | N18: =+M18 -> 9.99
C19: tbd | G19: 9.99 | H19: 9.99 | I19: 9.99 | J19: =+I19 -> 9.99 | K19: =+J19 -> 9.99 | L19: =+K19 -> 9.99 | M19: =+L19 -> 9.99 | N19: =+M19 -> 9.99
B21: Interest Expense | G21: {=SUMPRODUCT(G3:G7*G15:G19)} -> 355.625 | H21: {=SUMPRODUCT(H3:H7*H15:H19)} -> 367 | I21: {=SUMPRODUCT(I3:I7*I15:I19)} -> 348.375 | J21: {=SUMPRODUCT(J3:J7*J15:J19)} -> 331.125 | K21: {=SUMPRODUCT(K3:K7*K15:K19)} -> 316.75 | L21: {=SUMPRODUCT(L3:L7*L15:L19)} -> 302.375 | M21: {=SUMPRODUCT(M3:M7*M15:M19)} -> 288 | N21: {=SUMPRODUCT(N3:N7*N15:N19)} -> 273.625
